<?xml version="1.0"?>
<sdf version="1.6" xmlns:xacro="http://www.ros.org/wiki/xacro" name="rumbo">
<xacro:macro name="namespaced_rumbo" params="namespace x y z yaw">
<model name="${namespace}">
  <pose>${x} ${y} ${z} 0 0 ${yaw}</pose>
  <static>false</static>
  <link name="base_link">
    <pose>0 0 0.07 0 0 0</pose>
    <inertial> <!--inertial properties of the link mass, inertia matrix-->
        <mass>3</mass>
        <inertia>
            <ixx>0.095329</ixx>
            <ixy>0</ixy>
            <ixz>0</ixz>
            <iyy>0.381317</iyy>
            <iyz>0</iyz>
            <izz>0.476646</izz>
        </inertia>
    </inertial>
    <visual name='visual'>
      <geometry>
        <cylinder><length>0.1</length><radius>0.16</radius></cylinder>
      </geometry>
      <material>
        <ambient>0.0 1 0.0 1</ambient>
        <diffuse>0.0 1 0.0 1</diffuse>
        <specular>0.0 1 0.0 1</specular>
      </material>
    </visual>
    <collision name='collision'>
      <geometry>
        <cylinder><length>0.1</length><radius>0.16</radius></cylinder>
      </geometry>
    </collision>
  </link>
  <link name="R_wheel">
    <pose>0.0 -0.16 0.04 -1.57 0 0</pose>
        <inertial>
        <mass>1</mass>
        <inertia>
            <ixx>0.043333</ixx>
            <ixy>0</ixy>
            <ixz>0</ixz>
            <iyy>0.043333</iyy>
            <iyz>0</iyz>
            <izz>0.08</izz>
        </inertia>
    </inertial>
    <visual name='visual'>
      <geometry>
        <cylinder><length>0.02</length><radius>0.04</radius></cylinder>
      </geometry>
    </visual>
    <collision name='collision'>
      <geometry>
        <cylinder><length>0.02</length><radius>0.04</radius></cylinder>
      </geometry>
    </collision>
  </link>

  <link name="L_wheel">
    <pose>0.0 0.16 0.04 -1.57 0 0</pose>
    <inertial>
      <mass>1</mass>
      <inertia>
        <ixx>0.043333</ixx>
        <ixy>0</ixy>
        <ixz>0</ixz>
        <iyy>0.043333</iyy>
        <iyz>0</iyz>
        <izz>0.08</izz>
      </inertia>
    </inertial>
    <visual name='visual'>
      <geometry>
        <cylinder><length>0.02</length><radius>0.04</radius></cylinder>
      </geometry>
    </visual>
    <collision name='collision'>
      <geometry>
        <cylinder><length>0.02</length><radius>0.04</radius></cylinder>
      </geometry>
    </collision>
  </link>

  <link name="caster1">
    <pose> 0.14 0.0 0.02 0 0 0</pose>
    <inertial>
      <mass>1</mass>
      <inertia>
        <ixx>0.016</ixx>
        <ixy>0</ixy>
        <ixz>0</ixz>
        <iyy>0.016</iyy>
        <iyz>0</iyz>
        <izz>0.016</izz>
      </inertia>
    </inertial>
    <visual name='visual'>
      <geometry>
        <sphere><radius>0.02</radius></sphere>
      </geometry>
    </visual>
    <collision name='collision'>
      <geometry>
        <sphere><radius>0.02</radius></sphere>
      </geometry>
      <surface>
        <friction>
          <ode>
            <mu>0</mu>
            <mu2>0</mu2>
            <slip1>1.0</slip1>
            <slip2>1.0</slip2>
          </ode>
        </friction>
      </surface>
    </collision>
  </link>

  <link name="caster2">
    <pose> -0.14 0.0 0.02 0 0 0</pose>
    <inertial>
      <mass>1.5</mass>
      <inertia>
        <ixx>0.016</ixx>
        <ixy>0</ixy>
        <ixz>0</ixz>
        <iyy>0.016</iyy>
        <iyz>0</iyz>
        <izz>0.016</izz>
      </inertia>
    </inertial>
    <visual name='visual'>
      <geometry>
        <sphere><radius>0.02</radius></sphere>
      </geometry>
    </visual>
    <collision name='collision'>
      <geometry>
        <sphere><radius>0.02</radius></sphere>
      </geometry>
      <surface>
        <friction>
          <ode>
            <mu>0</mu>
            <mu2>0</mu2>
            <slip1>1.0</slip1>
            <slip2>1.0</slip2>
          </ode>
        </friction>
      </surface>
    </collision>
  </link>

  <link name="base_laser">
    <pose> 0.14 0.0 0.12 0 0 0</pose>
    <visual name='visual'>
      <geometry>
        <sphere><radius>0.02</radius></sphere>
      </geometry>
      <material>
        <ambient>1.0 0.0 0.0 1</ambient>
        <diffuse>1.0 0.0 0.0 1</diffuse>
        <specular>1.0 0.0 0.0 1</specular>
      </material>
    </visual>
    <collision name='collision'>
      <geometry>
        <sphere><radius>0.02</radius></sphere>
      </geometry>
    </collision>
    <sensor type="ray" name="lidar_sensor">
      <pose>0 0 0.02 0 0 0</pose>
      <always_on>1</always_on>
      <update_rate>30</update_rate>
      <ray>
        <scan>
          <horizontal>
            <samples>36</samples>
            <resolution>1</resolution>
            <min_angle>-3.14</min_angle>
            <max_angle>3.14</max_angle>
          </horizontal>
        </scan>
        <range>
          <min>0.10</min>
          <max>12.0</max>
          <resolution>0.01</resolution>
        </range>
      </ray>
      <plugin name="gazebo_ros_lidar" filename="libgazebo_ros_ray_sensor.so">
        <ros>
          <namespace>/${namespace}</namespace>
          <remapping>~/out:=scan</remapping>
        </ros>
        <output_type>sensor_msgs/LaserScan</output_type>
        <frame_name>base_laser</frame_name>
      </plugin>
    </sensor>
  </link>

  <joint type="revolute" name="base_to_R_wheel" >
    <pose>0 0 0 0 0 0</pose>
    <parent>base_link</parent>
    <child>R_wheel</child>
    <axis>
      <xyz>0 0 1</xyz>
    </axis>
    <limit>
      <lower>-1.79769e+308</lower>    <!--negative infinity-->
      <upper>1.79769e+308</upper>     <!--positive infinity-->
    </limit>
  </joint>

  <joint type="revolute" name="base_to_L_wheel" >
    <pose>0 0 0 0 0 0</pose>
    <parent>base_link</parent>
    <child>L_wheel</child>
    <axis>
      <xyz>0 0 1</xyz>
    </axis>
    <limit>
      <lower>-1.79769e+308</lower>    <!--negative infinity-->
      <upper>1.79769e+308</upper>     <!--positive infinity-->
    </limit>
  </joint>

  <joint name='caster_wheel1' type='ball'>
    <pose>0 0 0 0 0 0</pose>
    <parent>base_link</parent>
    <child>caster1</child>
  </joint>

  <joint name='caster_wheel2' type='ball'>
    <pose>0 0 0 0 0 0</pose>
    <parent>base_link</parent>
    <child>caster2</child>
  </joint>
  <joint name='base_laser_to_base' type='fixed'>
    <pose>0 0 0 0 0 0</pose>
    <parent>base_link</parent>
    <child>base_laser</child>
  </joint>

  <!--PLUGINS-->
  <plugin name="differential_drive_controller" filename="libgazebo_ros_diff_drive.so">
    <ros>
      <namespace>/${namespace}</namespace>
    </ros>
    <update_rate>62</update_rate>
    <left_joint>base_to_L_wheel</left_joint>
    <right_joint>base_to_R_wheel</right_joint>
    <wheel_separation>0.30</wheel_separation>
    <wheel_diameter>0.08</wheel_diameter>
    <wheel_acceleration>0.001</wheel_acceleration>
    <wheel_torque>0.002</wheel_torque>
    <command_topic>cmd_vel</command_topic>
    <odometry_topic>odom</odometry_topic>
    <odometry_frame>odom</odometry_frame>
    <robot_base_frame>base_link</robot_base_frame>
    <odometry_source>1</odometry_source>
    <publish_wheel_tf>false</publish_wheel_tf>
    <publish_odom>true</publish_odom>
    <publish_odom_tf>true</publish_odom_tf>
    <publish_wheel_joint_state>true</publish_wheel_joint_state>
    <legacy_mode>true</legacy_mode>
  </plugin>
</model>
</xacro:macro>
<xacro:namespaced_rumbo namespace="rumbo1" x="0" y="0" z="0.1" yaw="0"/>
</sdf>
